<?xml version="1.0" encoding="utf-8"?>
<!-- This URDF was automatically created by SolidWorks to URDF Exporter! Originally created by Stephen Brawner (brawner@gmail.com) 
     Commit Version: 1.6.0-4-g7f85cfe  Build Version: 1.6.7995.38578
     For more information, please see http://wiki.ros.org/sw_urdf_exporter -->
<robot
  name="dofbot">
  <link
    name="base_link">
    <inertial>
      <origin
        xyz="0.0239187360478796 -3.57286167253252E-06 0.0211670949981378"
        rpy="0 0 0" />
      <mass
        value="0.092958030858417" />
      <inertia
        ixx="8.46656134554647E-05"
        ixy="-9.60566398377124E-10"
        ixz="-1.8609628025435E-07"
        iyy="0.000341595426050822"
        iyz="-8.8960223243723E-10"
        izz="0.000425234311347401" />
    </inertial>
    <visual>
      <origin
        xyz="0 0 0"
        rpy="0 0 0" />
      <geometry>
        <mesh
          filename="package://dofbot/meshes/base_link.STL" />
      </geometry>
      <material
        name="">
        <color
          rgba="0.752941176470588 0.752941176470588 0.752941176470588 1" />
      </material>
    </visual>
    <collision>
      <origin
        xyz="0 0 0"
        rpy="0 0 0" />
      <geometry>
        <mesh
          filename="package://dofbot/meshes/base_link.STL" />
      </geometry>
    </collision>
  </link>
  <link
    name="arm1_Link">
    <inertial>
      <origin
        xyz="-7.43526328791932E-06 9.46661311882556E-05 0.0134507813164057"
        rpy="0 0 0" />
      <mass
        value="0.0188575206024817" />
      <inertia
        ixx="4.11728499100027E-06"
        ixy="1.80448315998037E-12"
        ixz="-1.06920580366416E-09"
        iyy="3.57439741198647E-06"
        iyz="6.13388044344299E-12"
        izz="6.05161576281479E-06" />
    </inertial>
    <visual>
      <origin
        xyz="0 0 0"
        rpy="0 0 0" />
      <geometry>
        <mesh
          filename="package://dofbot/meshes/arm1_Link.STL" />
      </geometry>
      <material
        name="">
        <color
          rgba="0.752941176470588 0.752941176470588 0.752941176470588 1" />
      </material>
    </visual>
    <collision>
      <origin
        xyz="0 0 0"
        rpy="0 0 0" />
      <geometry>
        <mesh
          filename="package://dofbot/meshes/arm1_Link.STL" />
      </geometry>
    </collision>
  </link>
  <joint
    name="arm1_Joint1"
    type="revolute">
    <origin
      xyz="0.069961 -1.6275E-05 0.068089"
      rpy="0 0 0" />
    <parent
      link="base_link" />
    <child
      link="arm1_Link" />
    <axis
      xyz="0 0 1" />
    <limit
      lower="-1.57"
      upper="1.57"
      effort="10"
      velocity="1000" />
  </joint>
  <link
    name="arm2_Link">
    <inertial>
      <origin
        xyz="-0.00365103479312762 -0.0189411797238544 0.0324309388532535"
        rpy="0 0 0" />
      <mass
        value="0.0174591699364493" />
      <inertia
        ixx="6.8699584147489E-06"
        ixy="1.10105943907958E-09"
        ixz="1.95333874160451E-09"
        iyy="5.64400490119962E-06"
        iyz="-2.15957304397495E-09"
        izz="3.08536112016155E-06" />
    </inertial>
    <visual>
      <origin
        xyz="0 0 0"
        rpy="0 0 0" />
      <geometry>
        <mesh
          filename="package://dofbot/meshes/arm2_Link.STL" />
      </geometry>
      <material
        name="">
        <color
          rgba="0.752941176470588 0.752941176470588 0.752941176470588 1" />
      </material>
    </visual>
    <collision>
      <origin
        xyz="0 0 0"
        rpy="0 0 0" />
      <geometry>
        <mesh
          filename="package://dofbot/meshes/arm2_Link.STL" />
      </geometry>
    </collision>
  </link>
  <joint
    name="arm2_joint"
    type="revolute">
    <origin
      xyz="-2.1581E-05 0.01885 0.038929"
      rpy="0 0 0" />
    <parent
      link="arm1_Link" />
    <child
      link="arm2_Link" />
    <axis
      xyz="0 1 0" />
    <limit
      lower="-1.57"
      upper="1.57"
      effort="10"
      velocity="1000" />
  </joint>
  <link
    name="arm3_Link">
    <inertial>
      <origin
        xyz="-0.00221538819573511 0.0138711909916294 0.0533121647004448"
        rpy="0 0 0" />
      <mass
        value="0.0354565671305204" />
      <inertia
        ixx="1.66869680056466E-05"
        ixy="1.10754557023219E-09"
        ixz="2.30689146957008E-08"
        iyy="1.10999518077607E-05"
        iyz="-2.41471347168069E-09"
        izz="8.77619856969404E-06" />
    </inertial>
    <visual>
      <origin
        xyz="0 0 0"
        rpy="0 0 0" />
      <geometry>
        <mesh
          filename="package://dofbot/meshes/arm3_Link.STL" />
      </geometry>
      <material
        name="">
        <color
          rgba="0.752941176470588 0.752941176470588 0.752941176470588 1" />
      </material>
    </visual>
    <collision>
      <origin
        xyz="0 0 0"
        rpy="0 0 0" />
      <geometry>
        <mesh
          filename="package://dofbot/meshes/arm3_Link.STL" />
      </geometry>
    </collision>
  </link>
  <joint
    name="arm3_Joint"
    type="revolute">
    <origin
      xyz="-5.5192E-05 -0.032957 0.08421"
      rpy="0 0 0" />
    <parent
      link="arm2_Link" />
    <child
      link="arm3_Link" />
    <axis
      xyz="0 1 0" />
    <limit
      lower="-1.57"
      upper="1.57"
      effort="10"
      velocity="1000" />
  </joint>
  <link
    name="arm4_Link">
    <inertial>
      <origin
        xyz="-0.00174186781645215 0.0139066239416856 0.0358119448415425"
        rpy="0 0 0" />
      <mass
        value="0.0222705568678127" />
      <inertia
        ixx="6.10376537972283E-06"
        ixy="9.51665090136291E-10"
        ixz="-3.66924778539692E-07"
        iyy="7.13318864238188E-06"
        iyz="-1.06484654159689E-09"
        izz="4.52922346761454E-06" />
    </inertial>
    <visual>
      <origin
        xyz="0 0 0"
        rpy="0 0 0" />
      <geometry>
        <mesh
          filename="package://dofbot/meshes/arm4_Link.STL" />
      </geometry>
      <material
        name="">
        <color
          rgba="0.752941176470588 0.752941176470588 0.752941176470588 1" />
      </material>
    </visual>
    <collision>
      <origin
        xyz="0 0 0"
        rpy="0 0 0" />
      <geometry>
        <mesh
          filename="package://dofbot/meshes/arm4_Link.STL" />
      </geometry>
    </collision>
  </link>
  <joint
    name="arm4_Joint"
    type="revolute">
    <origin
      xyz="-0.00040197 0.00040438 0.12614"
      rpy="0 0 0" />
    <parent
      link="arm3_Link" />
    <child
      link="arm4_Link" />
    <axis
      xyz="0 1 0" />
    <limit
      lower="-1.57"
      upper="1.57"
      effort="10"
      velocity="1000" />
  </joint>
  <link
    name="arm5_Link">
    <inertial>
      <origin
        xyz="0.0191388422294388 0.0026281227850543 -0.028755621624735"
        rpy="0 0 0" />
      <mass
        value="0.0384945180443885" />
      <inertia
        ixx="6.96411602459758E-06"
        ixy="1.94226296149185E-08"
        ixz="2.30318973395024E-08"
        iyy="2.47354529932262E-06"
        iyz="8.48918280912568E-09"
        izz="6.16283968272157E-06" />
    </inertial>
    <visual>
      <origin
        xyz="0 0 0"
        rpy="0 0 0" />
      <geometry>
        <mesh
          filename="package://dofbot/meshes/arm5_Link.STL" />
      </geometry>
      <material
        name="">
        <color
          rgba="0.203921568627451 0.227450980392157 0.250980392156863 1" />
      </material>
    </visual>
    <collision>
      <origin
        xyz="0 0 0"
        rpy="0 0 0" />
      <geometry>
        <mesh
          filename="package://dofbot/meshes/arm5_Link.STL" />
      </geometry>
    </collision>
  </link>
  <joint
    name="arm5_Joint"
    type="revolute">
    <origin
      xyz="-6.0888E-05 0.0138 0.077195"
      rpy="3.1416 0 0" />
    <parent
      link="arm4_Link" />
    <child
      link="arm5_Link" />
    <axis
      xyz="0 0 1" />
    <limit
      lower="-1.57"
      upper="1.57"
      effort="10"
      velocity="1000" />
  </joint>
  <link
    name="Rlink1_Link">
    <inertial>
      <origin
        xyz="-0.000177419223490044 0.000151927636637583 0.00344170190191967"
        rpy="0 0 0" />
      <mass
        value="0.0021842344020427" />
      <inertia
        ixx="2.5485951165225E-07"
        ixy="-5.1200784849125E-12"
        ixz="1.05050093908998E-10"
        iyy="1.93651104369493E-07"
        iyz="9.6316393757424E-09"
        izz="6.4752363434487E-08" />
    </inertial>
    <visual>
      <origin
        xyz="0 0 0"
        rpy="0 0 0" />
      <geometry>
        <mesh
          filename="package://dofbot/meshes/Rlink1_Link.STL" />
      </geometry>
      <material
        name="">
        <color
          rgba="0.533333333333333 0.533333333333333 0.533333333333333 1" />
      </material>
    </visual>
    <collision>
      <origin
        xyz="0 0 0"
        rpy="0 0 0" />
      <geometry>
        <mesh
          filename="package://dofbot/meshes/Rlink1_Link.STL" />
      </geometry>
    </collision>
  </link>
  <joint
    name="Rlink1_Joint"
    type="revolute">
    <origin
      xyz="-0.0031415 0.01265 -0.029948"
      rpy="3.1416 0 0" />
    <parent
      link="arm5_Link" />
    <child
      link="Rlink1_Link" />
    <axis
      xyz="1 0 0" />
    <limit
      lower="0"
      upper="1.57"
      effort="10"
      velocity="1000" />
  </joint>
  <link
    name="Rlink2_Link">
    <inertial>
      <origin
        xyz="0.0049875789430473 0.00668866088195564 0.0224309348303247"
        rpy="0 0 0" />
      <mass
        value="0.00231126837053933" />
      <inertia
        ixx="5.93484390861034E-07"
        ixy="5.7191445114195E-11"
        ixz="3.04909465128879E-10"
        iyy="5.64866051582192E-07"
        iyz="-1.03294291287441E-07"
        izz="4.24862869617146E-08" />
    </inertial>
    <visual>
      <origin
        xyz="0 0 0"
        rpy="0 0 0" />
      <geometry>
        <mesh
          filename="package://dofbot/meshes/Rlink2_Link.STL" />
      </geometry>
      <material
        name="">
        <color
          rgba="0.533333333333333 0.533333333333333 0.533333333333333 1" />
      </material>
    </visual>
    <collision>
      <origin
        xyz="0 0 0"
        rpy="0 0 0" />
      <geometry>
        <mesh
          filename="package://dofbot/meshes/Rlink2_Link.STL" />
      </geometry>
    </collision>
  </link>
  <joint
    name="Rlink2_Joint"
    type="revolute">
    <origin
      xyz="-0.0025416 -0.0010043 0.029982"
      rpy="0 0 0" />
    <parent
      link="Rlink1_Link" />
    <child
      link="Rlink2_Link" />
    <axis
      xyz="1 0 0" />
    <limit
      lower="-1.57"
      upper="1.57"
      effort="10"
      velocity="1000" />
    <mimic
      joint="Rlink1_Joint"
      multiplier="-1"
      offset="0" />
  </joint>
  <link
    name="Llink1_Link">
    <inertial>
      <origin
        xyz="0.00123283443416577 4.11827362748109E-05 -0.00580564774331011"
        rpy="0 0 0" />
      <mass
        value="0.00131648779674886" />
      <inertia
        ixx="2.01886977595084E-07"
        ixy="-7.24908062648337E-12"
        ixz="-9.36829572481688E-11"
        iyy="1.70422073015449E-07"
        iyz="-1.29249587766615E-08"
        izz="3.24803350744115E-08" />
    </inertial>
    <visual>
      <origin
        xyz="0 0 0"
        rpy="0 0 0" />
      <geometry>
        <mesh
          filename="package://dofbot/meshes/Llink1_Link.STL" />
      </geometry>
      <material
        name="">
        <color
          rgba="0.623529411764706 0.52156862745098 0.749019607843137 1" />
      </material>
    </visual>
    <collision>
      <origin
        xyz="0 0 0"
        rpy="0 0 0" />
      <geometry>
        <mesh
          filename="package://dofbot/meshes/Llink1_Link.STL" />
      </geometry>
    </collision>
  </link>
  <joint
    name="Llink1_Joint"
    type="revolute">
    <origin
      xyz="-0.0056665 -0.01223 -0.029697"
      rpy="0 0 0" />
    <parent
      link="arm5_Link" />
    <child
      link="Llink1_Link" />
    <axis
      xyz="1 0 0" />
    <limit
      lower="-1.57"
      upper="1.57"
      effort="10"
      velocity="1000" />
    <mimic
      joint="Rlink1_Joint"
      multiplier="-1"
      offset="0" />
  </joint>
  <link
    name="Llink2_Link">
    <inertial>
      <origin
        xyz="-0.00498766300071467 0.00691930205778919 0.0223608461909852"
        rpy="0 0 0" />
      <mass
        value="0.00231126837053932" />
      <inertia
        ixx="5.93484392308372E-07"
        ixy="-5.99556306092019E-11"
        ixz="-3.02996803908238E-10"
        iyy="5.62682696980491E-07"
        iyz="-1.08653043596381E-07"
        izz="4.4669640116073E-08" />
    </inertial>
    <visual>
      <origin
        xyz="0 0 0"
        rpy="0 0 0" />
      <geometry>
        <mesh
          filename="package://dofbot/meshes/Llink2_Link.STL" />
      </geometry>
      <material
        name="">
        <color
          rgba="0.533333333333333 0.533333333333333 0.533333333333333 1" />
      </material>
    </visual>
    <collision>
      <origin
        xyz="0 0 0"
        rpy="0 0 0" />
      <geometry>
        <mesh
          filename="package://dofbot/meshes/Llink2_Link.STL" />
      </geometry>
    </collision>
  </link>
  <joint
    name="Llink2_Joint"
    type="revolute">
    <origin
      xyz="-1.6765E-05 -0.0018113 -0.03032"
      rpy="3.1416 0 3.1416" />
    <parent
      link="Llink1_Link" />
    <child
      link="Llink2_Link" />
    <axis
      xyz="1 0 0" />
    <limit
      lower="-1.57"
      upper="1.57"
      effort="10"
      velocity="1000" />
    <mimic
      joint="Rlink1_Joint"
      multiplier="-1"
      offset="0" />
  </joint>
  <link
    name="Rlink3_Link">
    <inertial>
      <origin
        xyz="0.00489895779500876 -0.000216751686725427 0.0140189928378843"
        rpy="0 0 0" />
      <mass
        value="0.000604619671171983" />
      <inertia
        ixx="6.02457512544635E-08"
        ixy="-4.93197218606943E-13"
        ixz="3.25622855198614E-11"
        iyy="5.93569558721656E-08"
        iyz="8.97612174092086E-10"
        izz="1.33098393077239E-09" />
    </inertial>
    <visual>
      <origin
        xyz="0 0 0"
        rpy="0 0 0" />
      <geometry>
        <mesh
          filename="package://dofbot/meshes/Rlink3_Link.STL" />
      </geometry>
      <material
        name="">
        <color
          rgba="0.466666666666667 0.549019607843137 0.662745098039216 1" />
      </material>
    </visual>
    <collision>
      <origin
        xyz="0 0 0"
        rpy="0 0 0" />
      <geometry>
        <mesh
          filename="package://dofbot/meshes/Rlink3_Link.STL" />
      </geometry>
    </collision>
  </link>
  <joint
    name="Rlink3_Joint"
    type="revolute">
    <origin
      xyz="-0.0056765 0.0044999 -0.047947"
      rpy="3.1416 0 0" />
    <parent
      link="arm5_Link" />
    <child
      link="Rlink3_Link" />
    <axis
      xyz="1 0 0" />
    <limit
      lower="-1.57"
      upper="1.57"
      effort="10"
      velocity="1000" />
    <mimic
      joint="Rlink1_Joint"
      multiplier="1"
      offset="0" />
  </joint>
  <link
    name="Llink3_Link">
    <inertial>
      <origin
        xyz="0.004898957018708 -0.000311074993197471 -0.0140172173215368"
        rpy="0 0 0" />
      <mass
        value="0.000604619671171983" />
      <inertia
        ixx="6.02457512509097E-08"
        ixy="-7.14896077230261E-13"
        ixz="-3.25614361131708E-11"
        iyy="5.93422523775309E-08"
        iyz="-1.28789595317735E-09"
        izz="1.34568742896039E-09" />
    </inertial>
    <visual>
      <origin
        xyz="0 0 0"
        rpy="0 0 0" />
      <geometry>
        <mesh
          filename="package://dofbot/meshes/Llink3_Link.STL" />
      </geometry>
      <material
        name="">
        <color
          rgba="0.466666666666667 0.549019607843137 0.662745098039216 1" />
      </material>
    </visual>
    <collision>
      <origin
        xyz="0 0 0"
        rpy="0 0 0" />
      <geometry>
        <mesh
          filename="package://dofbot/meshes/Llink3_Link.STL" />
      </geometry>
    </collision>
  </link>
  <joint
    name="Llink3_Joint"
    type="revolute">
    <origin
      xyz="-0.0056765 -0.0045001 -0.047947"
      rpy="0 0 0" />
    <parent
      link="arm5_Link" />
    <child
      link="Llink3_Link" />
    <axis
      xyz="1 0 0" />
    <limit
      lower="-1.57"
      upper="1.57"
      effort="10"
      velocity="1000" />
    <mimic
      joint="Rlink1_Joint"
      multiplier="-1"
      offset="0" />
  </joint>
  <link
    name="Gripping_point_Link">
    <inertial>
      <origin
        xyz="6.93889390390723E-18 0.00170811257593551 0"
        rpy="0 0 0" />
      <mass
        value="0.00108842918376294" />
      <inertia
        ixx="3.41300668691933E-08"
        ixy="1.30410193447813E-23"
        ixz="-1.4716195848163E-23"
        iyy="6.54468304980741E-08"
        iyz="-5.52450020434586E-24"
        izz="3.41300668691932E-08" />
    </inertial>
    <visual>
      <origin
        xyz="0 0 0"
        rpy="0 0 0" />
      <geometry>
        <mesh
          filename="package://dofbot/meshes/Gripping_point_Link.STL" />
      </geometry>
      <material
        name="">
        <color
          rgba="0.956862745098039 0.956862745098039 0.96078431372549 1" />
      </material>
    </visual>
    <collision>
      <origin
        xyz="0 0 0"
        rpy="0 0 0" />
      <geometry>
        <mesh
          filename="package://dofbot/meshes/Gripping_point_Link.STL" />
      </geometry>
    </collision>
  </link>
  <joint
    name="Gripping_Joint"
    type="revolute">
    <origin
      xyz="0 0 -0.00215"
      rpy="1.5712 -0.0003891 2.3562" />
    <parent
      link="arm5_Link" />
    <child
      link="Gripping_point_Link" />
    <axis
      xyz="0 0 1" />
    <limit
      lower="-1.57"
      upper="1.57"
      effort="10"
      velocity="1000" />
  </joint>
</robot>